Traceback (most recent call last):
  File "/home/local/ASURITE/nnjungle/.local/lib/python3.10/site-packages/concrete/fhe/representation/graph.py", line 178, in evaluate
    node_results[node] = node(*pred_results)
  File "/home/local/ASURITE/nnjungle/.local/lib/python3.10/site-packages/concrete/fhe/representation/node.py", line 216, in __call__
    result = self.evaluator(*args)
  File "/home/local/ASURITE/nnjungle/.local/lib/python3.10/site-packages/concrete/fhe/representation/evaluator.py", line 39, in __call__
    return self.operation(*args, *self.properties["args"], **self.properties["kwargs"])
  File "/home/local/ASURITE/nnjungle/.local/lib/python3.10/site-packages/concrete/fhe/extensions/table.py", line 127, in apply
    return table[key]
IndexError: index 246 is out of bounds for axis 0 with size 246

The above exception was the direct cause of the following exception:

Traceback (most recent call last):
  File "/home/local/ASURITE/nnjungle/.local/lib/python3.10/site-packages/concrete/fhe/representation/graph.py", line 467, in measure_bounds
    evaluation = self.evaluate(*sample)
  File "/home/local/ASURITE/nnjungle/.local/lib/python3.10/site-packages/concrete/fhe/representation/graph.py", line 180, in evaluate
    raise RuntimeError(
RuntimeError: Evaluation of the graph failed

%0 = x                                               # EncryptedScalar<uint1>
%1 = tlu(%0, table=[0 0 0 0 0 ... 1 1 1 1 1])        # EncryptedScalar<uint1>
^^^^^^^^^^^^^^^^^^^^^^^^^^^^^^^^^^^^^^^^^^^^^^^^^^^^^^^^^^^^^^^^^^^^^^^^^^^^^ evaluation of this node failed
return %1

The above exception was the direct cause of the following exception:

Traceback (most recent call last):
  File "/home/local/ASURITE/nnjungle/.local/lib/python3.10/site-packages/concrete/fhe/compilation/compiler.py", line 447, in compile
    self._evaluate("Compiling", inputset)
  File "/home/local/ASURITE/nnjungle/.local/lib/python3.10/site-packages/concrete/fhe/compilation/compiler.py", line 295, in _evaluate
    bounds = self.graph.measure_bounds(self.inputset)
  File "/home/local/ASURITE/nnjungle/.local/lib/python3.10/site-packages/concrete/fhe/representation/graph.py", line 476, in measure_bounds
    raise RuntimeError(message) from error
RuntimeError: Bound measurement using inputset[246] failed
