Traceback (most recent call last):
  File "/home/local/ASURITE/nnjungle/.local/lib/python3.10/site-packages/concrete/fhe/representation/node.py", line 57, in constant
    value = ValueDescription.of(constant)
  File "/home/local/ASURITE/nnjungle/.local/lib/python3.10/site-packages/concrete/fhe/values/value_description.py", line 100, in of
    raise ValueError(message)
ValueError: Concrete cannot represent array([[[[None, None, None, None, None, None, None, None, None, None,
          None, None, None, None, None, None, None, None, None, None,
          None, None, None, None]]]], dtype=object)

The above exception was the direct cause of the following exception:

Traceback (most recent call last):
  File "/home/local/ASURITE/nnjungle/.local/lib/python3.10/site-packages/concrete/fhe/tracing/tracer.py", line 100, in trace
    sanitized_tracers.append(Tracer.sanitize(tracer))
  File "/home/local/ASURITE/nnjungle/.local/lib/python3.10/site-packages/concrete/fhe/tracing/tracer.py", line 211, in sanitize
    computation = Node.constant(value)
  File "/home/local/ASURITE/nnjungle/.local/lib/python3.10/site-packages/concrete/fhe/representation/node.py", line 60, in constant
    raise ValueError(message) from error
ValueError: Constant array([[[[None, None, None, None, None, None, None, None, None, None,
          None, None, None, None, None, None, None, None, None, None,
          None, None, None, None]]]], dtype=object) is not supported

The above exception was the direct cause of the following exception:

Traceback (most recent call last):
  File "/home/local/ASURITE/nnjungle/.local/lib/python3.10/site-packages/concrete/fhe/compilation/compiler.py", line 447, in compile
    self._evaluate("Compiling", inputset)
  File "/home/local/ASURITE/nnjungle/.local/lib/python3.10/site-packages/concrete/fhe/compilation/compiler.py", line 292, in _evaluate
    self._trace(first_sample)
  File "/home/local/ASURITE/nnjungle/.local/lib/python3.10/site-packages/concrete/fhe/compilation/compiler.py", line 220, in _trace
    self.graph = Tracer.trace(self.function, parameters)
  File "/home/local/ASURITE/nnjungle/.local/lib/python3.10/site-packages/concrete/fhe/tracing/tracer.py", line 107, in trace
    raise ValueError(message) from error
ValueError: Function 'network_function' returned '[[[[None None None None None None None None None None None None None
    None None None None None None None None None None None]]]]', which is not supported
